Workbook

Sheet Легенда
B2: Робот-уборщик «Циклон» v2 — комплектующие и расчёт
B3: Прототип для вводной/итоговой защиты: 4 ведущих колеса, отвал 45 см под 30°, ESP32 + Raspberry Pi
B5: • Листы: «Комплектующие» (закупка), «Расчёт» (тяга, моторы, энергия — меняйте жёлтые ячейки), «Итоги» (сумма и бюджет).
B6: • Жёлтые ячейки с синим текстом — исходные данные: цены, количества, параметры расчёта. Остальное считается формулами.
B7: • Цены: жёлтые — найдены в российских магазинах 14.10.2026 (источник в последней колонке); оранжевые — оценка без проверки, уточнить при закупке. Розница; на AliExpress обычно дешевле, но доставка 2–4 недели.
B8: • Этап P0 — нужно для работающего прототипа; P1 — по желанию/если останется бюджет.
B9: • Колонка «Что изменилось» показывает отличие от исходного варианта (v1) и причину.
B10: • Расчёт — оценочный: коэффициенты трения и плотность снега надо проверить опытом с динамометром (см. документ).

Sheet Комплектующие
A1: № | B1: Группа | C1: Наименование | D1: Тип / пример | E1: Кол. | F1: Этап | G1: Назначение | H1: Что изменилось (v1 → v2) | I1: Цена за шт., ₽ | J1: Сумма, ₽ | K1: Источник цены
A2: 1 | B2: A. Управление | C2: Микроконтроллер | D2: ESP32 DevKit V1 (30 pin) | E2: 2 | F2: P0 | G2: Моторы, энкодеры, датчики, безопасность (+1 запасной) | H2: без изменений | I2: 550 | J2: =IF(ISNUMBER(I2),E2*I2,0) -> 1100 | K2: найдено 14.10.2026: ardu-shop.ru, ESP32 DevKit V1 DOIT 30 pins
A3: 2 | B3: A. Управление | C3: Одноплатный компьютер | D3: Raspberry Pi 4, 2–4 ГБ (или Pi 3B+/Zero 2 W) | E3: 1 | F3: P0 | G3: Метки ArUco, маршрут, веб-панель, бот | H3: из лаборатории ВИШ — в смету 0 ₽ | I3: 0 | J3: =IF(ISNUMBER(I3),E3*I3,0) -> 0 | K3: найдено 14.10.2026: из лаборатории ВИШ; купить — ≈5 000 ₽ по смете v1
A4: 3 | B4: A. Управление | C4: Карта памяти | D4: microSD 32 ГБ, класс A1 | E4: 1 | F4: P0 | G4: Raspberry Pi OS + ПО | H4: добавлено | I4: 500 | J4: =IF(ISNUMBER(I4),E4*I4,0) -> 500 | K4: ОЦЕНКА, проверить
A5: 4 | B5: A. Управление | C5: Камера | D5: Raspberry Pi Camera v2 (+шлейф 30–50 см) или USB-камера | E5: 1 | F5: P0 | G5: Метки ArUco у точек поворота | H5: назначение: метки вместо QR на стенах | I5: 820 | J5: =IF(ISNUMBER(I5),E5*I5,0) -> 820 | K5: найдено 14.10.2026: roboshop.spb.ru, OV5647 для Raspberry Pi
A6: 5 | B6: B. Привод | C6: Мотор-редуктор с энкодером | D6: JGB37-520, 12 В, 1:90…1:131 (≈ 60–80 об/мин) | E6: 4 | F6: P0 | G6: Полный привод 4×4, бортовой поворот | H6: было 2× JGA25-370 200 об/мин | I6: 1100 | J6: =IF(ISNUMBER(I6),E6*I6,0) -> 4400 | K6: найдено 14.10.2026: robotclass.ru 1000 ₽; compacttool.ru 1160 ₽
A7: 6 | B7: B. Привод | C7: Кронштейн мотора | D7: Для JGB37 (L-образный) | E7: 4 | F7: P0 | G7: Крепление к раме | H7: добавлено | I7: 150 | J7: =IF(ISNUMBER(I7),E7*I7,0) -> 600 | K7: ОЦЕНКА, проверить
A8: 7 | B8: B. Привод | C8: Колесо с протектором + хаб | D8: 85×38 мм, резина, посадка шестигранник 12 мм | E8: 4 | F8: P0 | G8: Сцепление на снегу | H8: все 4 колеса ведущие | I8: 500 | J8: =IF(ISNUMBER(I8),E8*I8,0) -> 2000 | K8: найдено 14.10.2026: robot-kit.ru, колесо 85×38 мм
A9: 8 | B9: B. Привод | C9: Переходник колеса на вал 6 мм | D9: Комплект из 2 шт. (под колесо 85×38 мм) | E9: 2 | F9: P0 | G9: Посадка колеса на вал JGB37 | H9: добавлено | I9: 150 | J9: =IF(ISNUMBER(I9),E9*I9,0) -> 300 | K9: найдено 14.10.2026: robot-kit.ru, 150 ₽ за 2 шт.
A10: 9 | B10: B. Привод | C10: Драйвер моторов | D10: IBT-2 (BTS7960, 43 А) | E10: 2 | F10: P0 | G10: Левый и правый борт (по 2 мотора параллельно) | H10: было TB6612FNG (1,2 А — мало) | I10: 580 | J10: =IF(ISNUMBER(I10),E10*I10,0) -> 1160 | K10: найдено 14.10.2026: compacttool.ru, IBT-2 BTS7960
A11: 10 | B11: B. Привод | C11: Буфер уровней 3,3 → 5 В | D11: 74HCT245 (DIP) или модуль на 74HCT | E11: 1 | F11: P0 | G11: Входы IBT-2 рассчитаны на 5 В | H11: добавлено | I11: 100 | J11: =IF(ISNUMBER(I11),E11*I11,0) -> 100 | K11: ОЦЕНКА, проверить
A12: 11 | B12: C. Датчики | C12: Гироскоп | D12: MPU6050 (GY-521) | E12: 1 | F12: P0 | G12: Удержание курса, повороты | H12: был опционален — стал обязательным | I12: 250 | J12: =IF(ISNUMBER(I12),E12*I12,0) -> 250 | K12: ОЦЕНКА, проверить
A13: 12 | B13: C. Датчики | C13: Ультразвуковой дальномер | D13: HC-SR04 | E13: 4 | F13: P0 | G13: 3 вперёд (Л/Ц/П) + 1 запасной | H13: на стойке выше отвала | I13: 150 | J13: =IF(ISNUMBER(I13),E13*I13,0) -> 600 | K13: ОЦЕНКА, проверить
... A20: 19 | B20: E. Питание | C20: Аккумулятор | D20: 18650 3000–3500 мА·ч, ток ≥ 8 А | E20: 4 | F20: P0 | G20: Сборка 4S1P, 14,4 В | H20: без изменений | I20: 600 | J20: =IF(ISNUMBER(I20),E20*I20,0) -> 2400 | K20: найдено 14.10.2026: amperkot.ru Samsung 30Q 600 ₽; LG HG2 от 390 ₽ (navipoisk.ru)
A21: 20 | B21: E. Питание | C21: Держатель/сборка | D21: Кассета 4×18650 или сварка никелевой лентой | E21: 1 | F21: P0 | H21: без изменений | I21: 150 | J21: =IF(ISNUMBER(I21),E21*I21,0) -> 150 | K21: ОЦЕНКА, проверить
A22: 21 | B22: E. Питание | C22: Плата защиты | D22: BMS 4S ≥ 10 А с балансировкой | E22: 1 | F22: P0 | G22: Защита от переразряда/перезаряда | H22: без изменений | I22: 230 | J22: =IF(ISNUMBER(I22),E22*I22,0) -> 230 | K22: найдено 14.10.2026: smdx.ru, BMS 4S 20A
A23: 22 | B23: E. Питание | C23: Зарядное устройство | D23: 16,8 В 2 А для 4S (через BMS) | E23: 1 | F23: P0 | G23: Заряжать только в тепле (> 0 °C) | H23: добавлено | I23: 700 | J23: =IF(ISNUMBER(I23),E23*I23,0) -> 700 | K23: ОЦЕНКА, проверить
A24: 23 | B24: E. Питание | C24: Понижающий DC-DC 5 В | D24: 5,1 В / 5 А (XL4015 или готовый 5 В 5 А) | E24: 1 | F24: P0 | G24: Raspberry Pi + ESP32 + датчики | H24: было MP1584 (3 А) — мало для Pi 4 | I24: 350 | J24: =IF(ISNUMBER(I24),E24*I24,0) -> 350 | K24: ОЦЕНКА, проверить
A25: 24 | B25: E. Питание | C25: Понижающий DC-DC 6 В | D25: 6 В / 3 А | E25: 1 | F25: P0 | G25: Отдельная шина сервопривода | H25: добавлено | I25: 250 | J25: =IF(ISNUMBER(I25),E25*I25,0) -> 250 | K25: ОЦЕНКА, проверить
A26: 25 | B26: E. Питание | C26: Предохранитель | D26: Автомобильный 7,5 А + держатель | E26: 1 | F26: P0 | G26: Защита проводки | H26: добавлено | I26: 100 | J26: =IF(ISNUMBER(I26),E26*I26,0) -> 100 | K26: ОЦЕНКА, проверить
A27: 26 | B27: E. Питание | C27: Выключатель | D27: Тумблер ≥ 10 А | E27: 1 | F27: P0 | G27: Главный выключатель | H27: без изменений | I27: 100 | J27: =IF(ISNUMBER(I27),E27*I27,0) -> 100 | K27: ОЦЕНКА, проверить
A28: 27 | B28: E. Питание | C28: Аварийная кнопка | D28: Грибок E-STOP, NC, ≥ 10 А | E28: 1 | F28: P0 | G28: Обесточивает моторы независимо от ПО | H28: добавлено | I28: 300 | J28: =IF(ISNUMBER(I28),E28*I28,0) -> 300 | K28: ОЦЕНКА, проверить
A29: 28 | B29: F. Корпус и монтаж | C29: Рама | D29: Фанера 6–8 мм или профиль 2020 + уголки | E29: 1 | F29: P0 | G29: Шасси 350×240 мм, база 200, колея 280 | H29: размеры изменены | I29: 600 | J29: =IF(ISNUMBER(I29),E29*I29,0) -> 600 | K29: ОЦЕНКА, проверить
A30: 29 | B30: F. Корпус и монтаж | C30: Пластик для 3D-печати | D30: PETG, 1 кг | E30: 1 | F30: P0 | G30: Кронштейны, стойка датчиков, корпус электроники | H30: без изменений | I30: 1500 | J30: =IF(ISNUMBER(I30),E30*I30,0) -> 1500 | K30: ОЦЕНКА, проверить (может дать лаборатория → 0)
A31: 30 | B31: F. Корпус и монтаж | C31: Балласт | D31: Стальные пластины/диски 2–4 кг | E31: 1 | F31: P0 | G31: Масса 8–12 кг → сцепление | H31: добавлено (можно бесплатно) | I31: 0 | J31: =IF(ISNUMBER(I31),E31*I31,0) -> 0 | K31: ОЦЕНКА, проверить (найти бесплатно)
A32: 31 | B32: F. Корпус и монтаж | C32: Провода и разъёмы | D32: Силовой 0,75–1,5 мм², XT30/XT60, JST, Dupont, термоусадка | E32: 1 | F32: P0 | G32: Монтаж | H32: без изменений | I32: 800 | J32: =IF(ISNUMBER(I32),E32*I32,0) -> 800 | K32: ОЦЕНКА, проверить
A33: 32 | B33: F. Корпус и монтаж | C33: Монтажная плата | D33: Макетная плата / плата-расширитель ESP32 с клеммами | E33: 1 | F33: P0 | G33: Пайка узла управления | H33: без изменений | I33: 200 | J33: =IF(ISNUMBER(I33),E33*I33,0) -> 200 | K33: ОЦЕНКА, проверить
... A35: 34 | B35: G. Для опытов | C35: Динамометр (кантер) | D35: Электронный, 10–20 кг | E35: 1 | F35: P0 | G35: Измерить сцепление и сопротивление отвала | H35: добавлено — главный инструмент проверки расчётов | I35: 600 | J35: =IF(ISNUMBER(I35),E35*I35,0) -> 600 | K35: ОЦЕНКА, проверить (можно взять в лаборатории → 0)
I36: Итого, ₽ | J36: =SUM(J2:J35) -> 22550

Sheet Расчёт
B2: Расчёт тяги, моторов и энергии (глава 3 эссе)
B3: Меняйте жёлтые ячейки — выводы ниже пересчитаются. Те же формулы — в calc/raschet.py.
B4: Исходные данные
B5: Масса робота с балластом m | C5: 10 | D5: кг | E5: Рекомендуем 8–12 кг. v1 — 3 кг
B6: Доля веса на ведущих колёсах | C6: 1 | E6: 4 ведущих = 1; 2 ведущих ≈ 0,5–0,6
B7: Коэффициент сцепления резина–снег μ | C7: 0.3 | E7: 0,15 рыхлый/накат … 0,45 влажный снег на асфальте. ПРОВЕРИТЬ динамометром
B8: Сопротивление качению c | C8: 0.08 | E8: Малые колёса по снегу/слякоти: 0,05–0,15
B9: Уклон дорожки | C9: 2 | D9: °
B10: Разгон a | C10: 0.2 | D10: м/с² | E10: Как в прошивке (accelMps2)
B11: Глубина свежего снега h | C11: 0.03 | D11: м | E11: Целевая для демонстрации: до 3–4 см
B12: Плотность снега ρ | C12: 120 | D12: кг/м³ | E12: Свежий 50–200, слежавшийся 200–400
B13: Трение кома снега μ_ком | C13: 0.5 | E13: Оценка
B14: Длина отвала B | C14: 0.45 | D14: м
B15: Угол отвала к поперечному направлению α | C15: 30 | D15: ° | E15: 0 — прямой отвал (снег копится перед роботом)
B16: Коэффициент замедления скольжения снега | C16: 1.5 | E16: Снег скользит по отвалу медленнее идеала
B17: Запас на неучтённое | C17: 1.5 | D17: ×
B18: Диаметр колеса D | C18: 0.1 | D18: м
B19: Число ведущих моторов | C19: 4 | D19: шт.
B20: КПД передачи мотор → колесо | C20: 0.9 | E20: Колесо прямо на валу редуктора
B21: Момент блокировки мотора | C21: 5 | D21: кг·см | E21: JGB37-520 1:90…1:131: продавцы дают 5–8+; берём осторожно
B22: Обороты холостого хода | C22: 70 | D22: об/мин | E22: При 12 В
B23: Колея W | C23: 0.28 | D23: м | E23: Между центрами левого и правого колёс
B24: База L | C24: 0.2 | D24: м | E24: Между осями. L < W — легче поворачивать
B25: Боковое трение колёс μ_бок | C25: 0.3 | E25: Снег ≈ 0,3; сухой асфальт ≈ 0,7
B27: Силы
B28: Тяга по сцеплению | C28: =C7*C5*9.81*C6*COS(RADIANS(C9)) -> 29.412072 | D28: Н | E28: Больше этой силы колёса не передадут — начнут буксовать
B29: Снег, собираемый на 1 м пути | C29: =C12*C11*C14*COS(RADIANS(C15)) -> 1.4029612 | D29: кг/м
B30: Снег на отвале (установившийся режим) | C30: =C29*C14/(2*SIN(RADIANS(C15)))*C16 -> 0.94699878 | D30: кг | E30: Снег скользит вдоль наклонного отвала и сходит с заднего края
B31: Сопротивление качению | C31: =C8*C5*9.81*COS(RADIANS(C9)) -> 7.8432192 | D31: Н
B32: Подъём на уклон | C32: =C5*9.81*SIN(RADIANS(C9)) -> 3.4236406 | D32: Н
B33: Разгон | C33: =C5*C10 -> 2 | D33: Н
B34: Сопротивление отвала | C34: =C13*C30*9.81 -> 4.645029 | D34: Н
B35: Итого сопротивление | C35: =SUM(C31:C34) -> 17.911889 | D35: Н
B36: Итого с запасом | C36: =C35*C17 -> 26.867833 | D36: Н
B37: Запас по сцеплению | C37: =C28-C36 -> 2.5442388 | D37: Н | E37: Должен быть > 0
B38: Вывод | C38: =IF(C37>=0,"тяги хватает","колёса будут буксовать — нужна масса/4×4/меньше снега") -> тяги хватает
B39: Прямой отвал упрётся в сцепление через | C39: =C28/(C13*C12*C11*C14*9.81) -> 3.7014475 | D39: м | E39: Почему отвал ставим под углом
B41: Моторы
B42: Момент на один мотор (рабочий) | C42: =C35*(C18/2)/(C19*C20)*100/9.81 -> 2.5359453 | D42: кг·см
B43: Доля от момента блокировки | C43: =C42/C21 -> 0.50718906 | E43: Лучше < 0,5; при > 0,7 мотор греется и теряет скорость
...

Sheet Итоги
B2: Итоги и бюджет
B4: Позиций P0 | C4: =COUNTIF(Комплектующие!$F$2:$F$35,"P0") -> 32
B5: Позиций P1 | C5: =COUNTIF(Комплектующие!$F$2:$F$35,"P1") -> 2
B6: Сумма P0 по найденным ценам, ₽ | C6: =SUMIFS(Комплектующие!$J$2:$J$35,Комплектующие!$F$2:$F$35,"P0",Комплектующие!$K$2:$K$35,"найдено*") -> 13250 | D6: остальное в P0 — оценки
B7: Сумма P0, ₽ | C7: =SUMIFS(Комплектующие!$J$2:$J$35,Комплектующие!$F$2:$F$35,"P0") -> 21800
B8: Сумма P1, ₽ | C8: =SUMIFS(Комплектующие!$J$2:$J$35,Комплектующие!$F$2:$F$35,"P1") -> 750
B9: Резерв, % | C9: 0.1 | D9: допущение, меняется
B10: P0 с резервом, ₽ | C10: =C7*(1+C9) -> 23980
B11: Бюджет проекта, ₽ | C11: 28000 | D11: из заявки: 25 000–30 000 ₽ (ваша смета v1 — ~28 000 ₽ с резервом)
B12: Остаток бюджета после P0, ₽ | C12: =C11-C10 -> 4020
B13: На человека (6 в команде), P0 с резервом, ₽ | C13: =C10/6 -> 3996.6667
B15: Не включено: инструмент, доставка, Raspberry Pi (из лаборатории).
